An error occurred while executing the following cell:
------------------
timer = Timer()
animator = Animator(xlabel="epoch", xlim=[1, num_epochs], legend=["train loss", "train acc", "test acc"])
num_batches = len(train_iter)
device = torch.device(f"cuda:{0}")

for epoch in range(num_epochs):
    # Sum of training loss, sum of training accuracy, no. of examples
    metric = Accumulator(3)
    for i, (X, y) in enumerate(train_iter):
        timer.start()
        batch = {}
        batch["image"] = jnp.reshape(jnp.float32(X), (-1, 96, 96, 1))
        batch["label"] = jnp.float32(y)
        state, metrics = train_step(state, batch)
        metric.add(metrics["loss"] * X.shape[0], metrics["numcorrect"], X.shape[0])
        timer.stop()
        train_l = metric[0] / metric[2]
        train_acc = metric[1] / metric[2]
        if (i + 1) % (num_batches // 5) == 0 or i == num_batches - 1:
            animator.add(epoch + (i + 1) / num_batches, (train_l, train_acc, None))

    test_acc = eval_model(state, test_iter)
    animator.add(epoch + 1, (None, None, test_acc))


print(f"{metric[2] * num_epochs / timer.sum():.1f} examples/sec " f"on {str(device)}")
print(f"loss {train_l:.3f}, train acc {train_acc:.3f}, " f"test acc {test_acc:.3f}")
------------------

---------------------------------------------------------------------------
Empty                                     Traceback (most recent call last)
~/miniconda3/envs/py37/lib/python3.7/site-packages/torch/utils/data/dataloader.py in _try_get_data(self, timeout)
   1010         try:
-> 1011             data = self._data_queue.get(timeout=timeout)
   1012             return (True, data)

~/miniconda3/envs/py37/lib/python3.7/multiprocessing/queues.py in get(self, block, timeout)
    104                     if not self._poll(timeout):
--> 105                         raise Empty
    106                 elif not self._poll():

Empty: 

The above exception was the direct cause of the following exception:

RuntimeError                              Traceback (most recent call last)
/tmp/ipykernel_4032/1115125.py in <module>
      7     # Sum of training loss, sum of training accuracy, no. of examples
      8     metric = Accumulator(3)
----> 9     for i, (X, y) in enumerate(train_iter):
     10         timer.start()
     11         batch = {}

~/miniconda3/envs/py37/lib/python3.7/site-packages/torch/utils/data/dataloader.py in __next__(self)
    528             if self._sampler_iter is None:
    529                 self._reset()
--> 530             data = self._next_data()
    531             self._num_yielded += 1
    532             if self._dataset_kind == _DatasetKind.Iterable and \

~/miniconda3/envs/py37/lib/python3.7/site-packages/torch/utils/data/dataloader.py in _next_data(self)
   1205 
   1206             assert not self._shutdown and self._tasks_outstanding > 0
-> 1207             idx, data = self._get_data()
   1208             self._tasks_outstanding -= 1
   1209             if self._dataset_kind == _DatasetKind.Iterable:

~/miniconda3/envs/py37/lib/python3.7/site-packages/torch/utils/data/dataloader.py in _get_data(self)
   1171         else:
   1172             while True:
-> 1173                 success, data = self._try_get_data()
   1174                 if success:
   1175                     return data

~/miniconda3/envs/py37/lib/python3.7/site-packages/torch/utils/data/dataloader.py in _try_get_data(self, timeout)
   1022             if len(failed_workers) > 0:
   1023                 pids_str = ', '.join(str(w.pid) for w in failed_workers)
-> 1024                 raise RuntimeError('DataLoader worker (pid(s) {}) exited unexpectedly'.format(pids_str)) from e
   1025             if isinstance(e, queue.Empty):
   1026                 return (False, None)

RuntimeError: DataLoader worker (pid(s) 4148) exited unexpectedly
RuntimeError: DataLoader worker (pid(s) 4148) exited unexpectedly
